Workbook

Sheet Cover
A1: Portfolio Return & Risk Analyzer
A2: By : Krishna Sharma
A4: Project Objective
A5: Analyze a sample equity portfolio using actual historical daily prices to measure return, annualized volatility, Sharpe ratio and maximum drawdown. The workbook also compares the portfolio with the NIFTY 50 benchmark.
A8: How the Workbook Flows | D8: Core Formula Logic
A9: Sheet | B9: Purpose | D9: Metric | E9: Concept / Formula
A10: Portfolio | B10: Portfolio weights and editable assumptions | D10: Daily Return | E10: (Today Price / Previous Price) − 1
A11: Price Data | B11: Actual historical adjusted stock prices and NIFTY 50 index closes | D11: Portfolio Return | E11: Σ (asset return × portfolio weight)
A12: Returns | B12: Daily stock and weighted portfolio returns | D12: Annualized Volatility | E12: Daily return standard deviation × √252
A13: Risk Analysis | B13: Annualized metrics, cumulative performance and drawdowns | D13: Sharpe Ratio | E13: (Annualized return − risk-free rate) / annualized volatility
A14: Dashboard | B14: Summary and charts | D14: Drawdown | E14: (Current portfolio index / running peak) − 1

Sheet Portfolio
A1: Portfolio Setup & Assumptions
A3: Portfolio Allocation
A4: Asset | B4: Ticker | C4: Sector | D4: Weight | E4: Initial Allocation (₹) | F4: Input / Formula
A5: Reliance Industries | B5: RELIANCE.NS | C5: Energy / Conglomerate | D5: 0.25 | E5: =$B$14*D5 -> 25000 | F5: Weight = input
A6: HDFC Bank | B6: HDFCBANK.NS | C6: Financials | D6: 0.25 | E6: =$B$14*D6 -> 25000 | F6: Weight = input
A7: TCS | B7: TCS.NS | C7: Information Technology | D7: 0.2 | E7: =$B$14*D7 -> 20000 | F7: Weight = input
A8: ICICI Bank | B8: ICICIBANK.NS | C8: Financials | D8: 0.15 | E8: =$B$14*D8 -> 15000 | F8: Weight = input
A9: Infosys | B9: INFY.NS | C9: Information Technology | D9: 0.15 | E9: =$B$14*D9 -> 15000 | F9: Weight = input
A10: Total | D10: =SUM(D5:D9) -> 1 | E10: =SUM(E5:E9) -> 100000 | F10: Check = 100%
A12: Model Assumptions
A13: Assumption | B13: Value | D13: Model Checks
A14: Initial Portfolio Value (₹) | B14: 100000 | D14: Check | E14: Formula | F14: Status
A15: Risk-Free Rate (Annual) | B15: 0.065 | D15: Weights Total | E15: =D10 -> 1 | F15: =IF(ABS(E15-1)<0.0001,"OK","FIX WEIGHTS") -> OK
A16: Trading Days / Year | B16: 252 | D16: Number of Assets | E16: =COUNTA(A5:A9) -> 5 | F16: =IF(E16=5,"OK","CHECK") -> OK
A17: Analysis Start | B17: 44928 | D17: Data Observations | E17: =COUNTA('Price Data'!A5:A744) -> 740 | F17: =IF(E17>500,"OK","CHECK DATA") -> OK
A18: Analysis End | B18: 46022
A19: Price Data Type | B19: Actual historical adjusted stock prices + NIFTY 50 index close

Sheet Price Data
A1: Historical Adjusted Price Data
A2: Actual historical data, 02-Jan-2023 to 31-Dec-2025. Stocks: Yahoo Finance/yfinance-derived adjusted prices. NIFTY 50: ^NSEI historical index close (for an index, Close is the adjusted-price series).
A4: Date | B4: Reliance Industries | C4: HDFC Bank | D4: TCS | E4: ICICI Bank | F4: Infosys | G4: NIFTY 50
A5: 44928 | B5: 1170.4779 | C5: 770.92725 | D5: 2893.5598 | E5: 880.6474 | F5: 1368.0974 | G5: 18197.449
A6: 44929 | B6: 1161.9125 | C6: 775.96826 | D6: 2937.8315 | E6: 879.57391 | F6: 1366.7958 | G6: 18232.551
A7: 44930 | B7: 1144.4182 | C7: 762.09949 | D7: 2940.7593 | E7: 877.3783 | F7: 1341.8845 | G7: 18042.949
A8: 44931 | B8: 1142.3735 | C8: 757.20032 | D8: 2937.6099 | E8: 857.91034 | F8: 1324.2894 | G8: 17992.15
A9: 44932 | B9: 1152.7563 | C9: 754.69165 | D9: 2849.2888 | E9: 849.07886 | F9: 1300.3208 | G9: 17859.449
A10: 44935 | B10: 1179.9747 | C10: 756.159 | D10: 2945.4609 | E10: 852.25037 | F10: 1332.5931 | G10: 18101.199
A11: 44936 | B11: 1162.5259 | C11: 742.33759 | D11: 2915.6958 | E11: 840.54028 | F11: 1319.3972 | G11: 17914.15
A12: 44937 | B12: 1147.8716 | C12: 753.03497 | D12: 2953.2244 | E12: 845.37067 | F12: 1320.7438 | G12: 17895.699
A13: 44938 | B13: 1123.0842 | C13: 757.05841 | D13: 2958.2366 | E13: 839.85724 | F13: 1329.1372 | G13: 17858.199
A14: 44939 | B14: 1121.2668 | C14: 757.65009 | D14: 2993.9023 | E14: 852.34796 | F14: 1349.8292 | G14: 17956.6
A15: 44942 | B15: 1110.5885 | C15: 750.38434 | D15: 3025.2068 | E15: 844.34613 | F15: 1369.444 | G15: 17894.85
A16: 44943 | B16: 1126.356 | C16: 761.55511 | D16: 3065.448 | E16: 844.24854 | F16: 1382.0116 | G16: 18053.301
... A744: 46022 | B744: 1563.1726 | C744: 975.07288 | D744: 3106.8296 | E744: 1342.9 | F744: 1581.1842 | G744: 26129.6

Sheet Returns
A1: Daily Returns & Portfolio Return
A2: Daily return = Current Price / Previous Price − 1. Portfolio return = weighted sum of stock returns.
A4: Date | B4: Reliance Industries | C4: HDFC Bank | D4: TCS | E4: ICICI Bank | F4: Infosys | G4: Portfolio Return | H4: NIFTY 50
A5: ='Price Data'!A5 -> 44928 | B5: 0 | C5: 0 | D5: 0 | E5: 0 | F5: 0 | G5: 0 | H5: 0
A6: ='Price Data'!A6 -> 44929 | B6: =IFERROR('Price Data'!B6/'Price Data'!B5-1,0) -> -0.007317891 | C6: =IFERROR('Price Data'!C6/'Price Data'!C5-1,0) -> 0.0065388993 | D6: =IFERROR('Price Data'!D6/'Price Data'!D5-1,0) -> 0.015300091 | E6: =IFERROR('Price Data'!E6/'Price Data'!E5-1,0) -> -0.0012189741 | F6: =IFERROR('Price Data'!F6/'Price Data'!F5-1,0) -> -0.00095142037 | G6: =B6*Portfolio!$D$5+C6*Portfolio!$D$6+D6*Portfolio!$D$7+E6*Portfolio!$D$8+F6*Portfolio!$D$9 -> 0.0025397111 | H6: =IFERROR('Price Data'!G6/'Price Data'!G5-1,0) -> 0.0019289276
A7: ='Price Data'!A7 -> 44930 | B7: =IFERROR('Price Data'!B7/'Price Data'!B6-1,0) -> -0.015056438 | C7: =IFERROR('Price Data'!C7/'Price Data'!C6-1,0) -> -0.017872863 | D7: =IFERROR('Price Data'!D7/'Price Data'!D6-1,0) -> 0.00099656305 | E7: =IFERROR('Price Data'!E7/'Price Data'!E6-1,0) -> -0.0024962287 | F7: =IFERROR('Price Data'!F7/'Price Data'!F6-1,0) -> -0.018226026 | G7: =B7*Portfolio!$D$5+C7*Portfolio!$D$6+D7*Portfolio!$D$7+E7*Portfolio!$D$8+F7*Portfolio!$D$9 -> -0.011141351 | H7: =IFERROR('Price Data'!G7/'Price Data'!G6-1,0) -> -0.010399069
A8: ='Price Data'!A8 -> 44931 | B8: =IFERROR('Price Data'!B8/'Price Data'!B7-1,0) -> -0.0017866526 | C8: =IFERROR('Price Data'!C8/'Price Data'!C7-1,0) -> -0.0064285175 | D8: =IFERROR('Price Data'!D8/'Price Data'!D7-1,0) -> -0.0010709527 | E8: =IFERROR('Price Data'!E8/'Price Data'!E7-1,0) -> -0.022188783 | F8: =IFERROR('Price Data'!F8/'Price Data'!F7-1,0) -> -0.013112226 | G8: =B8*Portfolio!$D$5+C8*Portfolio!$D$6+D8*Portfolio!$D$7+E8*Portfolio!$D$8+F8*Portfolio!$D$9 -> -0.0075631344 | H8: =IFERROR('Price Data'!G8/'Price Data'!G7-1,0) -> -0.0028154393
A9: ='Price Data'!A9 -> 44932 | B9: =IFERROR('Price Data'!B9/'Price Data'!B8-1,0) -> 0.0090888069 | C9: =IFERROR('Price Data'!C9/'Price Data'!C8-1,0) -> -0.0033130823 | D9: =IFERROR('Price Data'!D9/'Price Data'!D8-1,0) -> -0.030065614 | E9: =IFERROR('Price Data'!E9/'Price Data'!E8-1,0) -> -0.010294178 | F9: =IFERROR('Price Data'!F9/'Price Data'!F8-1,0) -> -0.018099237 | G9: =B9*Portfolio!$D$5+C9*Portfolio!$D$6+D9*Portfolio!$D$7+E9*Portfolio!$D$8+F9*Portfolio!$D$9 -> -0.0088282039 | H9: =IFERROR('Price Data'!G9/'Price Data'!G8-1,0) -> -0.0073755037
A10: ='Price Data'!A10 -> 44935 | B10: =IFERROR('Price Data'!B10/'Price Data'!B9-1,0) -> 0.023611567 | C10: =IFERROR('Price Data'!C10/'Price Data'!C9-1,0) -> 0.001944299 | D10: =IFERROR('Price Data'!D10/'Price Data'!D9-1,0) -> 0.033753026 | E10: =IFERROR('Price Data'!E10/'Price Data'!E9-1,0) -> 0.0037352347 | F10: =IFERROR('Price Data'!F10/'Price Data'!F9-1,0) -> 0.024818752 | G10: =B10*Portfolio!$D$5+C10*Portfolio!$D$6+D10*Portfolio!$D$7+E10*Portfolio!$D$8+F10*Portfolio!$D$9 -> 0.01742267 | H10: =IFERROR('Price Data'!G10/'Price Data'!G9-1,0) -> 0.013536252
A11: ='Price Data'!A11 -> 44936 | B11: =IFERROR('Price Data'!B11/'Price Data'!B10-1,0) -> -0.01478748 | C11: =IFERROR('Price Data'!C11/'Price Data'!C10-1,0) -> -0.018278446 | D11: =IFERROR('Price Data'!D11/'Price Data'!D10-1,0) -> -0.010105426 | E11: =IFERROR('Price Data'!E11/'Price Data'!E10-1,0) -> -0.013740191 | F11: =IFERROR('Price Data'!F11/'Price Data'!F10-1,0) -> -0.0099024394 | G11: =B11*Portfolio!$D$5+C11*Portfolio!$D$6+D11*Portfolio!$D$7+E11*Portfolio!$D$8+F11*Portfolio!$D$9 -> -0.013833961 | H11: =IFERROR('Price Data'!G11/'Price Data'!G10-1,0) -> -0.010333505
A12: ='Price Data'!A12 -> 44937 | B12: =IFERROR('Price Data'!B12/'Price Data'!B11-1,0) -> -0.012605566 | C12: =IFERROR('Price Data'!C12/'Price Data'!C11-1,0) -> 0.014410408 | D12: =IFERROR('Price Data'!D12/'Price Data'!D11-1,0) -> 0.012871221 | E12: =IFERROR('Price Data'!E12/'Price Data'!E11-1,0) -> 0.00574676 | F12: =IFERROR('Price Data'!F12/'Price Data'!F11-1,0) -> 0.0010205855 | G12: =B12*Portfolio!$D$5+C12*Portfolio!$D$6+D12*Portfolio!$D$7+E12*Portfolio!$D$8+F12*Portfolio!$D$9 -> 0.0040405565 | H12: =IFERROR('Price Data'!G12/'Price Data'!G11-1,0) -> -0.0010299775
A13: ='Price Data'!A13 -> 44938 | B13: =IFERROR('Price Data'!B13/'Price Data'!B12-1,0) -> -0.021594187 | C13: =IFERROR('Price Data'!C13/'Price Data'!C12-1,0) -> 0.0053429623 | D13: =IFERROR('Price Data'!D13/'Price Data'!D12-1,0) -> 0.0016971982 | E13: =IFERROR('Price Data'!E13/'Price Data'!E12-1,0) -> -0.0065219057 | F13: =IFERROR('Price Data'!F13/'Price Data'!F12-1,0) -> 0.0063550802 | G13: =B13*Portfolio!$D$5+C13*Portfolio!$D$6+D13*Portfolio!$D$7+E13*Portfolio!$D$8+F13*Portfolio!$D$9 -> -0.0037483903 | H13: =IFERROR('Price Data'!G13/'Price Data'!G12-1,0) -> -0.0020954755
A14: ='Price Data'!A14 -> 44939 | B14: =IFERROR('Price Data'!B14/'Price Data'!B13-1,0) -> -0.001618207 | C14: =IFERROR('Price Data'!C14/'Price Data'!C13-1,0) -> 0.00078154446 | D14: =IFERROR('Price Data'!D14/'Price Data'!D13-1,0) -> 0.01205643 | E14: =IFERROR('Price Data'!E14/'Price Data'!E13-1,0) -> 0.014872436 | F14: =IFERROR('Price Data'!F14/'Price Data'!F13-1,0) -> 0.015568006 | G14: =B14*Portfolio!$D$5+C14*Portfolio!$D$6+D14*Portfolio!$D$7+E14*Portfolio!$D$8+F14*Portfolio!$D$9 -> 0.0067681866 | H14: =IFERROR('Price Data'!G14/'Price Data'!G13-1,0) -> 0.0055100959
A15: ='Price Data'!A15 -> 44942 | B15: =IFERROR('Price Data'!B15/'Price Data'!B14-1,0) -> -0.0095234643 | C15: =IFERROR('Price Data'!C15/'Price Data'!C14-1,0) -> -0.0095898452 | D15: =IFERROR('Price Data'!D15/'Price Data'!D14-1,0) -> 0.010456067 | E15: =IFERROR('Price Data'!E15/'Price Data'!E14-1,0) -> -0.0093879864 | F15: =IFERROR('Price Data'!F15/'Price Data'!F14-1,0) -> 0.01453128 | G15: =B15*Portfolio!$D$5+C15*Portfolio!$D$6+D15*Portfolio!$D$7+E15*Portfolio!$D$8+F15*Portfolio!$D$9 -> -0.00191562 | H15: =IFERROR('Price Data'!G15/'Price Data'!G14-1,0) -> -0.0034388471
A16: ='Price Data'!A16 -> 44943 | B16: =IFERROR('Price Data'!B16/'Price Data'!B15-1,0) -> 0.014197388 | C16: =IFERROR('Price Data'!C16/'Price Data'!C15-1,0) -> 0.01488674 | D16: =IFERROR('Price Data'!D16/'Price Data'!D15-1,0) -> 0.01330197 | E16: =IFERROR('Price Data'!E16/'Price Data'!E15-1,0) -> -0.00011558674 | F16: =IFERROR('Price Data'!F16/'Price Data'!F15-1,0) -> 0.009177175 | G16: =B16*Portfolio!$D$5+C16*Portfolio!$D$6+D16*Portfolio!$D$7+E16*Portfolio!$D$8+F16*Portfolio!$D$9 -> 0.011290664 | H16: =IFERROR('Price Data'!G16/'Price Data'!G15-1,0) -> 0.0088545685
A17: ='Price Data'!A17 -> 44944 | B17: =IFERROR('Price Data'!B17/'Price Data'!B16-1,0) -> -0.0016540394 | C17: =IFERROR('Price Data'!C17/'Price Data'!C16-1,0) -> 0.017651869 | D17: =IFERROR('Price Data'!D17/'Price Data'!D16-1,0) -> 0.0034336367 | E17: =IFERROR('Price Data'!E17/'Price Data'!E16-1,0) -> 0.0050279898 | F17: =IFERROR('Price Data'!F17/'Price Data'!F16-1,0) -> 0.0038324633 | G17: =B17*Portfolio!$D$5+C17*Portfolio!$D$6+D17*Portfolio!$D$7+E17*Portfolio!$D$8+F17*Portfolio!$D$9 -> 0.0060152527 | H17: =IFERROR('Price Data'!G17/'Price Data'!G16-1,0) -> 0.0062065563
... A744: ='Price Data'!A744 -> 46022 | B744: =IFERROR('Price Data'!B744/'Price Data'!B743-1,0) -> 0.019872749 | C744: =IFERROR('Price Data'!C744/'Price Data'!C743-1,0) -> 0.00030274078 | D744: =IFERROR('Price Data'!D744/'Price Data'!D743-1,0) -> -0.012504658 | E744: =IFERROR('Price Data'!E744/'Price Data'!E743-1,0) -> 0.00029796977 | F744: =IFERROR('Price Data'!F744/'Price Data'!F743-1,0) -> -0.0038233377 | G744: =B744*Portfolio!$D$5+C744*Portfolio!$D$6+D744*Portfolio!$D$7+E744*Portfolio!$D$8+F744*Portfolio!$D$9 -> 0.0020141357 | H744: =IFERROR('Price Data'!G744/'Price Data'!G743-1,0) -> 0.0073538342

Sheet Risk Analysis
A1: Risk & Performance Analysis
A3: Annualized Metrics
A4: Asset | B4: Annualized Return | C4: Annualized Volatility | D4: Sharpe Ratio | E4: Maximum Drawdown
A5: Reliance Industries | B5: =('Price Data'!B744/'Price Data'!B5)^(365/(Portfolio!$B$18-Portfolio!$B$17))-1 -> 0.1013352 | C5: =_xlfn.SINGLE(_xlfn.STDEV.S(Returns!B6:B744))*SQRT(Portfolio!$B$16) -> 0.20065114 | D5: =(B5-Portfolio!$B$15)/C5 -> 0.18108645 | E5: —
A6: HDFC Bank | B6: =('Price Data'!C744/'Price Data'!C5)^(365/(Portfolio!$B$18-Portfolio!$B$17))-1 -> 0.081531018 | C6: =_xlfn.SINGLE(_xlfn.STDEV.S(Returns!C6:C744))*SQRT(Portfolio!$B$16) -> 0.18471887 | D6: =(B6-Portfolio!$B$15)/C6 -> 0.08949285 | E6: —
A7: TCS | B7: =('Price Data'!D744/'Price Data'!D5)^(365/(Portfolio!$B$18-Portfolio!$B$17))-1 -> 0.024010477 | C7: =_xlfn.SINGLE(_xlfn.STDEV.S(Returns!D6:D744))*SQRT(Portfolio!$B$16) -> 0.19763317 | D7: =(B7-Portfolio!$B$15)/C7 -> -0.20740204 | E7: —
A8: ICICI Bank | B8: =('Price Data'!E744/'Price Data'!E5)^(365/(Portfolio!$B$18-Portfolio!$B$17))-1 -> 0.15116181 | C8: =_xlfn.SINGLE(_xlfn.STDEV.S(Returns!E6:E744))*SQRT(Portfolio!$B$16) -> 0.17645905 | D8: =(B8-Portfolio!$B$15)/C8 -> 0.4882822 | E8: —
A9: Infosys | B9: =('Price Data'!F744/'Price Data'!F5)^(365/(Portfolio!$B$18-Portfolio!$B$17))-1 -> 0.04948033 | C9: =_xlfn.SINGLE(_xlfn.STDEV.S(Returns!F6:F744))*SQRT(Portfolio!$B$16) -> 0.23749018 | D9: =(B9-Portfolio!$B$15)/C9 -> -0.065348682 | E9: —
A10: Portfolio | B10: =(B754/B15)^(365/(A754-A15))-1 -> 0.09131943 | C10: =_xlfn.SINGLE(_xlfn.STDEV.S(Returns!G6:G744))*SQRT(Portfolio!$B$16) -> 0.13396618 | D10: =(B10-Portfolio!$B$15)/C10 -> 0.19646325 | E10: =MIN(D15:D754) -> -0.146751
A11: NIFTY 50 | B11: =('Price Data'!G744/'Price Data'!G5)^(365/(Portfolio!$B$18-Portfolio!$B$17))-1 -> 0.12829316 | C11: =_xlfn.SINGLE(_xlfn.STDEV.S(Returns!H6:H744))*SQRT(Portfolio!$B$16) -> 0.12016528 | D11: =(B11-Portfolio!$B$15)/C11 -> 0.52671748 | E11: =MIN(G15:G754) -> -0.15766678
A13: Cumulative Performance & Drawdown
A14: Date | B14: Portfolio Index | C14: Portfolio Running Peak | D14: Portfolio Drawdown | E14: NIFTY 50 Index | F14: NIFTY Running Peak | G14: NIFTY 50 Drawdown
A15: =Returns!A5 -> 44928 | B15: 100 | C15: 100 | D15: 0 | E15: 100 | F15: 100 | G15: 0
A16: =Returns!A6 -> 44929 | B16: =B15*(1+Returns!G6) -> 100.25397 | C16: =MAX(C15,B16) -> 100.25397 | D16: =B16/C16-1 -> 0 | E16: =E15*(1+Returns!H6) -> 100.19289 | F16: =MAX(F15,E16) -> 100.19289 | G16: =E16/F16-1 -> 0
A17: =Returns!A7 -> 44930 | B17: =B16*(1+Returns!G7) -> 99.137006 | C17: =MAX(C16,B17) -> 100.25397 | D17: =B17/C17-1 -> -0.011141351 | E17: =E16*(1+Returns!H7) -> 99.15098 | F17: =MAX(F16,E17) -> 100.19289 | G17: =E17/F17-1 -> -0.010399069
A18: =Returns!A8 -> 44931 | B18: =B17*(1+Returns!G8) -> 98.38722 | C18: =MAX(C17,B18) -> 100.25397 | D18: =B18/C18-1 -> -0.018620222 | E18: =E17*(1+Returns!H8) -> 98.871826 | F18: =MAX(F17,E18) -> 100.19289 | G18: =E18/F18-1 -> -0.013185231
A19: =Returns!A9 -> 44932 | B19: =B18*(1+Returns!G9) -> 97.518638 | C19: =MAX(C18,B19) -> 100.25397 | D19: =B19/C19-1 -> -0.027284042 | E19: =E18*(1+Returns!H9) -> 98.142597 | F19: =MAX(F18,E19) -> 100.19289 | G19: =E19/F19-1 -> -0.020463487
A20: =Returns!A10 -> 44935 | B20: =B19*(1+Returns!G10) -> 99.217673 | C20: =MAX(C19,B20) -> 100.25397 | D20: =B20/C20-1 -> -0.010336734 | E20: =E19*(1+Returns!H10) -> 99.47108 | F20: =MAX(F19,E20) -> 100.19289 | G20: =E20/F20-1 -> -0.007204234
A21: =Returns!A11 -> 44936 | B21: =B20*(1+Returns!G11) -> 97.845099 | C21: =MAX(C20,B21) -> 100.25397 | D21: =B21/C21-1 -> -0.024027697 | E21: =E20*(1+Returns!H11) -> 98.443195 | F21: =MAX(F20,E21) -> 100.19289 | G21: =E21/F21-1 -> -0.017463294
A22: =Returns!A12 -> 44937 | B22: =B21*(1+Returns!G12) -> 98.240448 | C22: =MAX(C21,B22) -> 100.25397 | D22: =B22/C22-1 -> -0.020084226 | E22: =E21*(1+Returns!H12) -> 98.341801 | F22: =MAX(F21,E22) -> 100.19289 | G22: =E22/F22-1 -> -0.018475284
A23: =Returns!A13 -> 44938 | B23: =B22*(1+Returns!G13) -> 97.872204 | C23: =MAX(C22,B23) -> 100.25397 | D23: =B23/C23-1 -> -0.023757332 | E23: =E22*(1+Returns!H13) -> 98.135728 | F23: =MAX(F22,E23) -> 100.19289 | G23: =E23/F23-1 -> -0.020532046
A24: =Returns!A14 -> 44939 | B24: =B23*(1+Returns!G14) -> 98.534622 | C24: =MAX(C23,B24) -> 100.25397 | D24: =B24/C24-1 -> -0.01714994 | E24: =E23*(1+Returns!H14) -> 98.676465 | F24: =MAX(F23,E24) -> 100.19289 | G24: =E24/F24-1 -> -0.015135083
A25: =Returns!A15 -> 44942 | B25: =B24*(1+Returns!G15) -> 98.345867 | C25: =MAX(C24,B25) -> 100.25397 | D25: =B25/C25-1 -> -0.019032707 | E25: =E24*(1+Returns!H15) -> 98.337132 | F25: =MAX(F24,E25) -> 100.19289 | G25: =E25/F25-1 -> -0.018521883
A26: =Returns!A16 -> 44943 | B26: =B25*(1+Returns!G16) -> 99.456257 | C26: =MAX(C25,B26) -> 100.25397 | D26: =B26/C26-1 -> -0.0079569346 | E26: =E25*(1+Returns!H16) -> 99.207865 | F26: =MAX(F25,E26) -> 100.19289 | G26: =E26/F26-1 -> -0.0098313177
A27: =Returns!A17 -> 44944 | B27: =B26*(1+Returns!G17) -> 100.05451 | C27: =MAX(C26,B27) -> 100.25397 | D27: =B27/C27-1 -> -0.0019895449 | E27: =E26*(1+Returns!H17) -> 99.823604 | F27: =MAX(F26,E27) -> 100.19289 | G27: =E27/F27-1 -> -0.00368578
... A754: =Returns!A744 -> 46022 | B754: =B753*(1+Returns!G744) -> 129.94264 | C754: =MAX(C753,B754) -> 132.12152 | D754: =B754/C754-1 -> -0.016491513 | E754: =E753*(1+Returns!H744) -> 143.58935 | F754: =MAX(F753,E754) -> 144.06443 | G754: =E754/F754-1 -> -0.0032976428
C755: =MAX(C754,B755) -> 132.12152 | D755: =B755/C755-1 -> -1 | F755: =MAX(F754,E755) -> 144.06443 | G755: =E755/F755-1 -> -1
C756: =MAX(C755,B756) -> 132.12152 | D756: =B756/C756-1 -> -1 | F756: =MAX(F755,E756) -> 144.06443 | G756: =E756/F756-1 -> -1
C757: =MAX(C756,B757) -> 132.12152 | D757: =B757/C757-1 -> -1 | F757: =MAX(F756,E757) -> 144.06443 | G757: =E757/F757-1 -> -1
C758: =MAX(C757,B758) -> 132.12152 | D758: =B758/C758-1 -> -1 | F758: =MAX(F757,E758) -> 144.06443 | G758: =E758/F758-1 -> -1
C759: =MAX(C758,B759) -> 132.12152 | D759: =B759/C759-1 -> -1 | F759: =MAX(F758,E759) -> 144.06443 | G759: =E759/F759-1 -> -1
C760: =MAX(C759,B760) -> 132.12152 | D760: =B760/C760-1 -> -1 | F760: =MAX(F759,E760) -> 144.06443 | G760: =E760/F760-1 -> -1
C761: =MAX(C760,B761) -> 132.12152 | D761: =B761/C761-1 -> -1 | F761: =MAX(F760,E761) -> 144.06443 | G761: =E761/F761-1 -> -1
C762: =MAX(C761,B762) -> 132.12152 | D762: =B762/C762-1 -> -1 | F762: =MAX(F761,E762) -> 144.06443 | G762: =E762/F762-1 -> -1
C763: =MAX(C762,B763) -> 132.12152 | D763: =B763/C763-1 -> -1 | F763: =MAX(F762,E763) -> 144.06443 | G763: =E763/F763-1 -> -1
C764: =MAX(C763,B764) -> 132.12152 | D764: =B764/C764-1 -> -1 | F764: =MAX(F763,E764) -> 144.06443 | G764: =E764/F764-1 -> -1
C765: =MAX(C764,B765) -> 132.12152 | D765: =B765/C765-1 -> -1 | F765: =MAX(F764,E765) -> 144.06443 | G765: =E765/F765-1 -> -1
C766: =MAX(C765,B766) -> 132.12152 | D766: =B766/C766-1 -> -1 | F766: =MAX(F765,E766) -> 144.06443 | G766: =E766/F766-1 -> -1
... C797: =MAX(C796,B797) -> 132.12152 | D797: =B797/C797-1 -> -1 | F797: =MAX(F796,E797) -> 144.06443 | G797: =E797/F797-1 -> -1

Sheet Dashboard
A1: Portfolio Return & Risk Analyzer — Dashboard
A2: 5-stock Indian equity portfolio | Actual historical adjusted stock prices | NIFTY 50 benchmark | 02-Jan-2023 to 31-Dec-2025 | M2: Asset | N2: Weight | P2: Asset | Q2: Return | R2: Volatility | T2: Month | U2: Portfolio Index | V2: NIFTY 50 Index | W2: Portfolio Drawdown | X2: NIFTY 50 Drawdown
M3: Reliance Industries | N3: 0.25 | P3: Reliance Industries | Q3: ='Risk Analysis'!B5 -> 0.1013352 | R3: ='Risk Analysis'!C5 -> 0.20065114 | T3: Jan-23 | U3: ='Risk Analysis'!B15 -> 100 | V3: ='Risk Analysis'!E15 -> 100 | W3: ='Risk Analysis'!D15 -> 0 | X3: ='Risk Analysis'!G15 -> 0
A4: Annualized Return | D4: Annualized Volatility | G4: Sharpe Ratio | J4: Maximum Drawdown | M4: HDFC Bank | N4: 0.25 | P4: HDFC Bank | Q4: ='Risk Analysis'!B6 -> 0.081531018 | R4: ='Risk Analysis'!C6 -> 0.18471887 | T4: Jan-23 | U4: ='Risk Analysis'!B34 -> 97.930368 | V4: ='Risk Analysis'!E34 -> 96.985841 | W4: ='Risk Analysis'!D34 -> -0.027459023 | X4: ='Risk Analysis'!G34 -> -0.032008772
A5: ='Risk Analysis'!B10 -> 0.09131943 | D5: ='Risk Analysis'!C10 -> 0.13396618 | G5: ='Risk Analysis'!D10 -> 0.19646325 | J5: ='Risk Analysis'!E10 -> -0.146751 | M5: TCS | N5: 0.2 | P5: TCS | Q5: ='Risk Analysis'!B7 -> 0.024010477 | R5: ='Risk Analysis'!C7 -> 0.19763317 | T5: Feb-23 | U5: ='Risk Analysis'!B54 -> 97.458676 | V5: ='Risk Analysis'!E54 -> 95.577677 | W5: ='Risk Analysis'!D54 -> -0.04069831 | X5: ='Risk Analysis'!G54 -> -0.046063306
M6: ICICI Bank | N6: 0.15 | P6: ICICI Bank | Q6: ='Risk Analysis'!B8 -> 0.15116181 | R6: ='Risk Analysis'!C8 -> 0.17645905 | T6: Mar-23 | U6: ='Risk Analysis'!B73 -> 93.222733 | V6: ='Risk Analysis'!E73 -> 93.3411 | W6: ='Risk Analysis'!D73 -> -0.082393392 | X6: ='Risk Analysis'!G73 -> -0.068386019
M7: Infosys | N7: 0.15 | P7: Infosys | Q7: ='Risk Analysis'!B9 -> 0.04948033 | R7: ='Risk Analysis'!C9 -> 0.23749018 | T7: Apr-23 | U7: ='Risk Analysis'!B93 -> 97.185651 | V7: ='Risk Analysis'!E93 -> 99.272155 | W7: ='Risk Analysis'!D93 -> -0.043385737 | X7: ='Risk Analysis'!G93 -> -0.0091896511
P8: Portfolio | Q8: ='Risk Analysis'!B10 -> 0.09131943 | R8: ='Risk Analysis'!C10 -> 0.13396618 | T8: May-23 | U8: ='Risk Analysis'!B112 -> 99.240015 | V8: ='Risk Analysis'!E112 -> 101.65903 | W8: ='Risk Analysis'!D112 -> -0.023164299 | X8: ='Risk Analysis'!G112 -> 0
T9: Jun-23 | U9: ='Risk Analysis'!B132 -> 98.41302 | V9: ='Risk Analysis'!E132 -> 102.57207 | W9: ='Risk Analysis'!D132 -> -0.031304542 | X9: ='Risk Analysis'!G132 -> -0.010147486
T10: Jul-23 | U10: ='Risk Analysis'!B151 -> 104.2617 | V10: ='Risk Analysis'!E151 -> 108.50422 | W10: ='Risk Analysis'!D151 -> -0.027139451 | X10: ='Risk Analysis'!G151 -> -0.011719737
T11: Aug-23 | U11: ='Risk Analysis'!B171 -> 103.34655 | V11: ='Risk Analysis'!E171 -> 106.57318 | W11: ='Risk Analysis'!D171 -> -0.035678693 | X11: ='Risk Analysis'!G171 -> -0.029308092
T12: Sep-23 | U12: ='Risk Analysis'!B190 -> 106.82967 | V12: ='Risk Analysis'!E190 -> 110.96253 | W12: ='Risk Analysis'!D190 -> -0.0031778238 | X12: ='Risk Analysis'!G190 -> 0
T13: Oct-23 | U13: ='Risk Analysis'!B209 -> 101.58233 | V13: ='Risk Analysis'!E209 -> 108.43141 | W13: ='Risk Analysis'!D209 -> -0.052140533 | X13: ='Risk Analysis'!G209 -> -0.0228106
T14: Nov-23 | U14: ='Risk Analysis'!B229 -> 100.45383 | V14: ='Risk Analysis'!E229 -> 108.12202 | W14: ='Risk Analysis'!D229 -> -0.06267054 | X14: ='Risk Analysis'!G229 -> -0.025598823
T15: Dec-23 | U15: ='Risk Analysis'!B248 -> 106.11858 | V15: ='Risk Analysis'!E248 -> 114.99606 | W15: ='Risk Analysis'!D248 -> -0.012726921 | X15: ='Risk Analysis'!G248 -> -0.003369513
T16: Jan-24 | U16: ='Risk Analysis'!B268 -> 110.48398 | V16: ='Risk Analysis'!E268 -> 118.95733 | W16: ='Risk Analysis'!D268 -> -0.0096039734 | X16: ='Risk Analysis'!G268 -> -0.0060380098
T17: Feb-24 | U17: ='Risk Analysis'!B287 -> 112.89098 | V17: ='Risk Analysis'!E287 -> 119.70084 | W17: ='Risk Analysis'!D287 -> -0.015207843 | X17: ='Risk Analysis'!G287 -> -0.014252741
T18: Mar-24 | U18: ='Risk Analysis'!B307 -> 113.91216 | V18: ='Risk Analysis'!E307 -> 122.72407 | W18: ='Risk Analysis'!D307 -> -0.0107895 | X18: ='Risk Analysis'!G307 -> -0.0071531788
T19: Apr-24 | U19: ='Risk Analysis'!B326 -> 114.56887 | V19: ='Risk Analysis'!E326 -> 124.42815 | W19: ='Risk Analysis'!D326 -> -0.0055271569 | X19: ='Risk Analysis'!G326 -> -0.0010390218
T20: May-24 | U20: ='Risk Analysis'!B346 -> 110.89563 | V20: ='Risk Analysis'!E346 -> 121.1994 | W20: ='Risk Analysis'!D346 -> -0.037411362 | X20: ='Risk Analysis'!G346 -> -0.030702632
T21: Jun-24 | U21: ='Risk Analysis'!B365 -> 116.67505 | V21: ='Risk Analysis'!E365 -> 127.9858 | W21: ='Risk Analysis'!D365 -> 0 | X21: ='Risk Analysis'!G365 -> 0
T22: Jul-24 | U22: ='Risk Analysis'!B385 -> 124.36907 | V22: ='Risk Analysis'!E385 -> 133.64813 | W22: ='Risk Analysis'!D385 -> -0.0060130543 | X22: ='Risk Analysis'!G385 -> -0.00013562114
T23: Aug-24 | U23: ='Risk Analysis'!B404 -> 122.08055 | V23: ='Risk Analysis'!E404 -> 132.19215 | W23: ='Risk Analysis'!D404 -> -0.038707612 | X23: ='Risk Analysis'!G404 -> -0.038195377
T24: Sep-24 | U24: ='Risk Analysis'!B423 -> 129.27944 | V24: ='Risk Analysis'!E423 -> 138.91342 | W24: ='Risk Analysis'!D423 -> -0.00016205391 | X24: ='Risk Analysis'!G423 -> 0
T25: Sep-24 | U25: ='Risk Analysis'!B443 -> 128.81905 | V25: ='Risk Analysis'!E443 -> 141.83773 | W25: ='Risk Analysis'!D443 -> -0.020093072 | X25: ='Risk Analysis'!G443 -> -0.015456225
T26: Oct-24 | U26: ='Risk Analysis'!B462 -> 124.97282 | V26: ='Risk Analysis'!E462 -> 133.75034 | W26: ='Risk Analysis'!D462 -> -0.049350816 | X26: ='Risk Analysis'!G462 -> -0.071593559
T27: Nov-24 | U27: ='Risk Analysis'!B482 -> 127.88927 | V27: ='Risk Analysis'!E482 -> 133.39727 | W27: ='Risk Analysis'!D482 -> -0.027165783 | X27: ='Risk Analysis'!G482 -> -0.074044348
T28: Dec-24 | U28: ='Risk Analysis'!B501 -> 124.81216 | V28: ='Risk Analysis'!E501 -> 130.38998 | W28: ='Risk Analysis'!D501 -> -0.050572927 | X28: ='Risk Analysis'!G501 -> -0.094918964
T29: Jan-25 | U29: ='Risk Analysis'!B521 -> 122.33727 | V29: ='Risk Analysis'!E521 -> 127.24503 | W29: ='Risk Analysis'!D521 -> -0.069399029 | X29: ='Risk Analysis'!G521 -> -0.11674913
T30: Feb-25 | U30: ='Risk Analysis'!B540 -> 121.14332 | V30: ='Risk Analysis'!E540 -> 126.16878 | W30: ='Risk Analysis'!D540 -> -0.07848125 | X30: ='Risk Analysis'!G540 -> -0.12421973
T31: Mar-25 | U31: ='Risk Analysis'!B560 -> 117.85849 | V31: ='Risk Analysis'!E560 -> 125.88357 | W31: ='Risk Analysis'!D560 -> -0.1034684 | X31: ='Risk Analysis'!G560 -> -0.12619945
T32: Apr-25 | U32: ='Risk Analysis'!B579 -> 120.52815 | V32: ='Risk Analysis'!E579 -> 132.57655 | W32: ='Risk Analysis'!D579 -> -0.083160708 | X32: ='Risk Analysis'!G579 -> -0.079741225
T33: May-25 | U33: ='Risk Analysis'!B598 -> 127.40471 | V33: ='Risk Analysis'!E598 -> 137.08212 | W33: ='Risk Analysis'!D598 -> -0.030851784 | X33: ='Risk Analysis'!G598 -> -0.048466551
T34: Jun-25 | U34: ='Risk Analysis'!B618 -> 128.12681 | V34: ='Risk Analysis'!E618 -> 137.08789 | W34: ='Risk Analysis'!D618 -> -0.025358837 | X34: ='Risk Analysis'!G618 -> -0.048426469
T35: Jul-25 | U35: ='Risk Analysis'!B637 -> 128.41461 | V35: ='Risk Analysis'!E637 -> 138.20536 | W35: ='Risk Analysis'!D637 -> -0.02342782 | X35: ='Risk Analysis'!G637 -> -0.040669786
T36: Aug-25 | U36: ='Risk Analysis'!B657 -> 121.94004 | V36: ='Risk Analysis'!E657 -> 133.88305 | W36: ='Risk Analysis'!D657 -> -0.072665899 | X36: ='Risk Analysis'!G657 -> -0.070672353
T37: Sep-25 | U37: ='Risk Analysis'!B676 -> 121.42829 | V37: ='Risk Analysis'!E676 -> 136.13529 | W37: ='Risk Analysis'!D676 -> -0.076557697 | X37: ='Risk Analysis'!G676 -> -0.055038816
T38: Oct-25 | U38: ='Risk Analysis'!B696 -> 121.75324 | V38: ='Risk Analysis'!E696 -> 137.97703 | W38: ='Risk Analysis'!D696 -> -0.074086479 | X38: ='Risk Analysis'!G696 -> -0.042254648
T39: Nov-25 | U39: ='Risk Analysis'!B715 -> 123.93462 | V39: ='Risk Analysis'!E715 -> 140.66615 | W39: ='Risk Analysis'!D715 -> -0.057497456 | X39: ='Risk Analysis'!G715 -> -0.023588617
T40: Dec-25 | U40: ='Risk Analysis'!B735 -> 129.57533 | V40: ='Risk Analysis'!E735 -> 142.80023 | W40: ='Risk Analysis'!D735 -> -0.014600777 | X40: ='Risk Analysis'!G735 -> -0.0087751883
...
